Workbook

Sheet ダッシュボード
A1: ストロベリーボーイズ｜SEO/AIO・X統合運用 KPIダッシュボード
A3: 更新日 | B3: 2026-04-15
A4: 計測期間 | B4: 2026-04-15 〜 2026-12-31
A6: ■ 年間KGI (Key Goal Indicators)
A7: 領域 | B7: 指標 | C7: 目標 | D7: 現状 | E7: 進捗率 | F7: 残日数
A8: SEO | B8: 女性用風俗 横浜 順位 | C8: 1位 | D8: — | E8: =IF(D8="—",0,IF(ISNUMBER(D8),MAX(0,(11-D8)/10),0)) -> 0 | F8: =DATEDIF(TODAY(),DATE(2026,12,31),"D") -> 258
A9: SEO | B9: 女性用風俗 神奈川 順位 | C9: 1位 | D9: — | E9: =IF(D9="—",0,IF(ISNUMBER(D9),MAX(0,(11-D9)/10),0)) -> 0 | F9: =DATEDIF(TODAY(),DATE(2026,12,31),"D") -> 258
A10: SEO | B10: 女性用風俗 福岡 順位 | C10: 1位 | D10: — | E10: =IF(D10="—",0,IF(ISNUMBER(D10),MAX(0,(11-D10)/10),0)) -> 0 | F10: =DATEDIF(TODAY(),DATE(2026,12,31),"D") -> 258
A11: SEO | B11: 女性用風俗 博多 順位 | C11: 1位 | D11: — | E11: =IF(D11="—",0,IF(ISNUMBER(D11),MAX(0,(11-D11)/10),0)) -> 0 | F11: =DATEDIF(TODAY(),DATE(2026,12,31),"D") -> 258
A12: X公式 | B12: フォロワー数 | C12: 10000 | D12: 0 | E12: =D12/C12 -> 0 | F12: =DATEDIF(TODAY(),DATE(2026,12,31),"D") -> 258
A13: Xサブ | B13: フォロワー数 | C13: 3000 | D13: 0 | E13: =D13/C13 -> 0 | F13: =DATEDIF(TODAY(),DATE(2026,12,31),"D") -> 258
A14: AIO | B14: AI引用獲得KW数(20中) | C14: 10 | D14: 0 | E14: =D14/C14 -> 0 | F14: =DATEDIF(TODAY(),DATE(2026,12,31),"D") -> 258
A16: ■ X公式フォロワー成長ペース(必要純増数)
A17: フェーズ | B17: 期間 | C17: 期間日数 | D17: 純増目標 | E17: 1日平均
A18: 初速期 | B18: 4/15-6/30 | C18: 76 | D18: 1500 | E18: =D18/C18 -> 19.736842
A19: 加速期 | B19: 7/1-9/30 | C19: 92 | D19: 4500 | E19: =D19/C19 -> 48.913043
A20: 確定期 | B20: 10/1-12/31 | C20: 92 | D20: 4000 | E20: =D20/C20 -> 43.478261
A21: 合計 | B21: 4/15-12/31 | C21: =SUM(C18:C20) -> 260 | D21: =SUM(D18:D20) -> 10000 | E21: =D21/C21 -> 38.461538
A23: ■ X投稿パフォーマンスサマリー（直近7日）
A24: 指標 | B24: 直近7日 | C24: 前7日 | D24: 変化
A25: 合計インプレッション | B25: =SUM(日次ダイジェスト!D2:D8) -> 0 | C25: =SUM(日次ダイジェスト!D9:D15) -> 0 | D25: =IF(AND(ISNUMBER(B25),ISNUMBER(C25),C25>0),(B25-C25)/C25,"")
A26: 合計エンゲージメント | B26: =SUM(日次ダイジェスト!E2:E8) -> 0 | C26: =SUM(日次ダイジェスト!E9:E15) -> 0 | D26: =IF(AND(ISNUMBER(B26),ISNUMBER(C26),C26>0),(B26-C26)/C26,"")
A27: 平均ER(%) | B27: =IFERROR(B26/B25,"") | C27: =IFERROR(C26/C25,"") | D27: =IF(AND(ISNUMBER(B27),ISNUMBER(C27),C27>0),(B27-C27)/C27,"")
A28: フォロワー純増 | B28: =SUM(日次ダイジェスト!K2:K8) -> 0 | C28: =SUM(日次ダイジェスト!K9:K15) -> 0 | D28: =IF(AND(ISNUMBER(B28),ISNUMBER(C28),C28>0),(B28-C28)/C28,"")
A29: 最高Impピラー | B29: =IFERROR(INDEX(ピラー別分析!A4:A8,MATCH(MAX(ピラー別分析!C4:C8),ピラー別分析!C4:C8,0)),"") -> 共感・エンパワメント

Sheet X投稿ログ
A1: 投稿日 | B1: 時間帯 | C1: ピラー | D1: 投稿テキスト(冒頭40字) | E1: 画像有無 | F1: URL有無 | G1: インプレッション | H1: エンゲージメント | I1: いいね | J1: RT | K1: リプライ | L1: リンククリック | M1: ER(%) | N1: Imp/フォロワー比 | O1: スコア(自動) | P1: 勝因/敗因メモ
A2: 2026-04-15 | B2: 朝(7:30-8:30) | M2: =IF(AND(ISNUMBER(H2),ISNUMBER(G2),G2>0),H2/G2,"") | N2: =IF(AND(ISNUMBER(G2),G2>0),G2/IF(ISNUMBER(ダッシュボード!D12),ダッシュボード!D12,1),"") | O2: =IF(ISNUMBER(G2),G2*1+IF(ISNUMBER(H2),H2,0)*5+IF(ISNUMBER(J2),J2,0)*10+IF(ISNUMBER(K2),K2,0)*3,"")
A3: 2026-04-15 | B3: 昼(12:00-13:00) | M3: =IF(AND(ISNUMBER(H3),ISNUMBER(G3),G3>0),H3/G3,"") | N3: =IF(AND(ISNUMBER(G3),G3>0),G3/IF(ISNUMBER(ダッシュボード!D12),ダッシュボード!D12,1),"") | O3: =IF(ISNUMBER(G3),G3*1+IF(ISNUMBER(H3),H3,0)*5+IF(ISNUMBER(J3),J3,0)*10+IF(ISNUMBER(K3),K3,0)*3,"")
A4: 2026-04-15 | B4: 夕(19:00-20:00) | M4: =IF(AND(ISNUMBER(H4),ISNUMBER(G4),G4>0),H4/G4,"") | N4: =IF(AND(ISNUMBER(G4),G4>0),G4/IF(ISNUMBER(ダッシュボード!D12),ダッシュボード!D12,1),"") | O4: =IF(ISNUMBER(G4),G4*1+IF(ISNUMBER(H4),H4,0)*5+IF(ISNUMBER(J4),J4,0)*10+IF(ISNUMBER(K4),K4,0)*3,"")
A5: 2026-04-15 | B5: 夜1(22:00-22:30) | M5: =IF(AND(ISNUMBER(H5),ISNUMBER(G5),G5>0),H5/G5,"") | N5: =IF(AND(ISNUMBER(G5),G5>0),G5/IF(ISNUMBER(ダッシュボード!D12),ダッシュボード!D12,1),"") | O5: =IF(ISNUMBER(G5),G5*1+IF(ISNUMBER(H5),H5,0)*5+IF(ISNUMBER(J5),J5,0)*10+IF(ISNUMBER(K5),K5,0)*3,"")
A6: 2026-04-15 | B6: 夜2(23:00-23:30) | M6: =IF(AND(ISNUMBER(H6),ISNUMBER(G6),G6>0),H6/G6,"") | N6: =IF(AND(ISNUMBER(G6),G6>0),G6/IF(ISNUMBER(ダッシュボード!D12),ダッシュボード!D12,1),"") | O6: =IF(ISNUMBER(G6),G6*1+IF(ISNUMBER(H6),H6,0)*5+IF(ISNUMBER(J6),J6,0)*10+IF(ISNUMBER(K6),K6,0)*3,"")
A7: 2026-04-16 | B7: 朝(7:30-8:30) | M7: =IF(AND(ISNUMBER(H7),ISNUMBER(G7),G7>0),H7/G7,"") | N7: =IF(AND(ISNUMBER(G7),G7>0),G7/IF(ISNUMBER(ダッシュボード!D12),ダッシュボード!D12,1),"") | O7: =IF(ISNUMBER(G7),G7*1+IF(ISNUMBER(H7),H7,0)*5+IF(ISNUMBER(J7),J7,0)*10+IF(ISNUMBER(K7),K7,0)*3,"")
A8: 2026-04-16 | B8: 昼(12:00-13:00) | M8: =IF(AND(ISNUMBER(H8),ISNUMBER(G8),G8>0),H8/G8,"") | N8: =IF(AND(ISNUMBER(G8),G8>0),G8/IF(ISNUMBER(ダッシュボード!D12),ダッシュボード!D12,1),"") | O8: =IF(ISNUMBER(G8),G8*1+IF(ISNUMBER(H8),H8,0)*5+IF(ISNUMBER(J8),J8,0)*10+IF(ISNUMBER(K8),K8,0)*3,"")
A9: 2026-04-16 | B9: 夕(19:00-20:00) | M9: =IF(AND(ISNUMBER(H9),ISNUMBER(G9),G9>0),H9/G9,"") | N9: =IF(AND(ISNUMBER(G9),G9>0),G9/IF(ISNUMBER(ダッシュボード!D12),ダッシュボード!D12,1),"") | O9: =IF(ISNUMBER(G9),G9*1+IF(ISNUMBER(H9),H9,0)*5+IF(ISNUMBER(J9),J9,0)*10+IF(ISNUMBER(K9),K9,0)*3,"")
A10: 2026-04-16 | B10: 夜1(22:00-22:30) | M10: =IF(AND(ISNUMBER(H10),ISNUMBER(G10),G10>0),H10/G10,"") | N10: =IF(AND(ISNUMBER(G10),G10>0),G10/IF(ISNUMBER(ダッシュボード!D12),ダッシュボード!D12,1),"") | O10: =IF(ISNUMBER(G10),G10*1+IF(ISNUMBER(H10),H10,0)*5+IF(ISNUMBER(J10),J10,0)*10+IF(ISNUMBER(K10),K10,0)*3,"")
A11: 2026-04-16 | B11: 夜2(23:00-23:30) | M11: =IF(AND(ISNUMBER(H11),ISNUMBER(G11),G11>0),H11/G11,"") | N11: =IF(AND(ISNUMBER(G11),G11>0),G11/IF(ISNUMBER(ダッシュボード!D12),ダッシュボード!D12,1),"") | O11: =IF(ISNUMBER(G11),G11*1+IF(ISNUMBER(H11),H11,0)*5+IF(ISNUMBER(J11),J11,0)*10+IF(ISNUMBER(K11),K11,0)*3,"")
A12: 2026-04-17 | B12: 朝(7:30-8:30) | M12: =IF(AND(ISNUMBER(H12),ISNUMBER(G12),G12>0),H12/G12,"") | N12: =IF(AND(ISNUMBER(G12),G12>0),G12/IF(ISNUMBER(ダッシュボード!D12),ダッシュボード!D12,1),"") | O12: =IF(ISNUMBER(G12),G12*1+IF(ISNUMBER(H12),H12,0)*5+IF(ISNUMBER(J12),J12,0)*10+IF(ISNUMBER(K12),K12,0)*3,"")
A13: 2026-04-17 | B13: 昼(12:00-13:00) | M13: =IF(AND(ISNUMBER(H13),ISNUMBER(G13),G13>0),H13/G13,"") | N13: =IF(AND(ISNUMBER(G13),G13>0),G13/IF(ISNUMBER(ダッシュボード!D12),ダッシュボード!D12,1),"") | O13: =IF(ISNUMBER(G13),G13*1+IF(ISNUMBER(H13),H13,0)*5+IF(ISNUMBER(J13),J13,0)*10+IF(ISNUMBER(K13),K13,0)*3,"")
A14: 2026-04-17 | B14: 夕(19:00-20:00) | M14: =IF(AND(ISNUMBER(H14),ISNUMBER(G14),G14>0),H14/G14,"") | N14: =IF(AND(ISNUMBER(G14),G14>0),G14/IF(ISNUMBER(ダッシュボード!D12),ダッシュボード!D12,1),"") | O14: =IF(ISNUMBER(G14),G14*1+IF(ISNUMBER(H14),H14,0)*5+IF(ISNUMBER(J14),J14,0)*10+IF(ISNUMBER(K14),K14,0)*3,"")
A15: 2026-04-17 | B15: 夜1(22:00-22:30) | M15: =IF(AND(ISNUMBER(H15),ISNUMBER(G15),G15>0),H15/G15,"") | N15: =IF(AND(ISNUMBER(G15),G15>0),G15/IF(ISNUMBER(ダッシュボード!D12),ダッシュボード!D12,1),"") | O15: =IF(ISNUMBER(G15),G15*1+IF(ISNUMBER(H15),H15,0)*5+IF(ISNUMBER(J15),J15,0)*10+IF(ISNUMBER(K15),K15,0)*3,"")
A16: 2026-04-17 | B16: 夜2(23:00-23:30) | M16: =IF(AND(ISNUMBER(H16),ISNUMBER(G16),G16>0),H16/G16,"") | N16: =IF(AND(ISNUMBER(G16),G16>0),G16/IF(ISNUMBER(ダッシュボード!D12),ダッシュボード!D12,1),"") | O16: =IF(ISNUMBER(G16),G16*1+IF(ISNUMBER(H16),H16,0)*5+IF(ISNUMBER(J16),J16,0)*10+IF(ISNUMBER(K16),K16,0)*3,"")
A17: 2026-04-18 | B17: 朝(7:30-8:30) | M17: =IF(AND(ISNUMBER(H17),ISNUMBER(G17),G17>0),H17/G17,"") | N17: =IF(AND(ISNUMBER(G17),G17>0),G17/IF(ISNUMBER(ダッシュボード!D12),ダッシュボード!D12,1),"") | O17: =IF(ISNUMBER(G17),G17*1+IF(ISNUMBER(H17),H17,0)*5+IF(ISNUMBER(J17),J17,0)*10+IF(ISNUMBER(K17),K17,0)*3,"")
A18: 2026-04-18 | B18: 昼(12:00-13:00) | M18: =IF(AND(ISNUMBER(H18),ISNUMBER(G18),G18>0),H18/G18,"") | N18: =IF(AND(ISNUMBER(G18),G18>0),G18/IF(ISNUMBER(ダッシュボード!D12),ダッシュボード!D12,1),"") | O18: =IF(ISNUMBER(G18),G18*1+IF(ISNUMBER(H18),H18,0)*5+IF(ISNUMBER(J18),J18,0)*10+IF(ISNUMBER(K18),K18,0)*3,"")
A19: 2026-04-18 | B19: 夕(19:00-20:00) | M19: =IF(AND(ISNUMBER(H19),ISNUMBER(G19),G19>0),H19/G19,"") | N19: =IF(AND(ISNUMBER(G19),G19>0),G19/IF(ISNUMBER(ダッシュボード!D12),ダッシュボード!D12,1),"") | O19: =IF(ISNUMBER(G19),G19*1+IF(ISNUMBER(H19),H19,0)*5+IF(ISNUMBER(J19),J19,0)*10+IF(ISNUMBER(K19),K19,0)*3,"")
A20: 2026-04-18 | B20: 夜1(22:00-22:30) | M20: =IF(AND(ISNUMBER(H20),ISNUMBER(G20),G20>0),H20/G20,"") | N20: =IF(AND(ISNUMBER(G20),G20>0),G20/IF(ISNUMBER(ダッシュボード!D12),ダッシュボード!D12,1),"") | O20: =IF(ISNUMBER(G20),G20*1+IF(ISNUMBER(H20),H20,0)*5+IF(ISNUMBER(J20),J20,0)*10+IF(ISNUMBER(K20),K20,0)*3,"")
A21: 2026-04-18 | B21: 夜2(23:00-23:30) | M21: =IF(AND(ISNUMBER(H21),ISNUMBER(G21),G21>0),H21/G21,"") | N21: =IF(AND(ISNUMBER(G21),G21>0),G21/IF(ISNUMBER(ダッシュボード!D12),ダッシュボード!D12,1),"") | O21: =IF(ISNUMBER(G21),G21*1+IF(ISNUMBER(H21),H21,0)*5+IF(ISNUMBER(J21),J21,0)*10+IF(ISNUMBER(K21),K21,0)*3,"")
A22: 2026-04-19 | B22: 朝(7:30-8:30) | M22: =IF(AND(ISNUMBER(H22),ISNUMBER(G22),G22>0),H22/G22,"") | N22: =IF(AND(ISNUMBER(G22),G22>0),G22/IF(ISNUMBER(ダッシュボード!D12),ダッシュボード!D12,1),"") | O22: =IF(ISNUMBER(G22),G22*1+IF(ISNUMBER(H22),H22,0)*5+IF(ISNUMBER(J22),J22,0)*10+IF(ISNUMBER(K22),K22,0)*3,"")
A23: 2026-04-19 | B23: 昼(12:00-13:00) | M23: =IF(AND(ISNUMBER(H23),ISNUMBER(G23),G23>0),H23/G23,"") | N23: =IF(AND(ISNUMBER(G23),G23>0),G23/IF(ISNUMBER(ダッシュボード!D12),ダッシュボード!D12,1),"") | O23: =IF(ISNUMBER(G23),G23*1+IF(ISNUMBER(H23),H23,0)*5+IF(ISNUMBER(J23),J23,0)*10+IF(ISNUMBER(K23),K23,0)*3,"")
A24: 2026-04-19 | B24: 夕(19:00-20:00) | M24: =IF(AND(ISNUMBER(H24),ISNUMBER(G24),G24>0),H24/G24,"") | N24: =IF(AND(ISNUMBER(G24),G24>0),G24/IF(ISNUMBER(ダッシュボード!D12),ダッシュボード!D12,1),"") | O24: =IF(ISNUMBER(G24),G24*1+IF(ISNUMBER(H24),H24,0)*5+IF(ISNUMBER(J24),J24,0)*10+IF(ISNUMBER(K24),K24,0)*3,"")
A25: 2026-04-19 | B25: 夜1(22:00-22:30) | M25: =IF(AND(ISNUMBER(H25),ISNUMBER(G25),G25>0),H25/G25,"") | N25: =IF(AND(ISNUMBER(G25),G25>0),G25/IF(ISNUMBER(ダッシュボード!D12),ダッシュボード!D12,1),"") | O25: =IF(ISNUMBER(G25),G25*1+IF(ISNUMBER(H25),H25,0)*5+IF(ISNUMBER(J25),J25,0)*10+IF(ISNUMBER(K25),K25,0)*3,"")
A26: 2026-04-19 | B26: 夜2(23:00-23:30) | M26: =IF(AND(ISNUMBER(H26),ISNUMBER(G26),G26>0),H26/G26,"") | N26: =IF(AND(ISNUMBER(G26),G26>0),G26/IF(ISNUMBER(ダッシュボード!D12),ダッシュボード!D12,1),"") | O26: =IF(ISNUMBER(G26),G26*1+IF(ISNUMBER(H26),H26,0)*5+IF(ISNUMBER(J26),J26,0)*10+IF(ISNUMBER(K26),K26,0)*3,"")
A27: 2026-04-20 | B27: 朝(7:30-8:30) | M27: =IF(AND(ISNUMBER(H27),ISNUMBER(G27),G27>0),H27/G27,"") | N27: =IF(AND(ISNUMBER(G27),G27>0),G27/IF(ISNUMBER(ダッシュボード!D12),ダッシュボード!D12,1),"") | O27: =IF(ISNUMBER(G27),G27*1+IF(ISNUMBER(H27),H27,0)*5+IF(ISNUMBER(J27),J27,0)*10+IF(ISNUMBER(K27),K27,0)*3,"")
A28: 2026-04-20 | B28: 昼(12:00-13:00) | M28: =IF(AND(ISNUMBER(H28),ISNUMBER(G28),G28>0),H28/G28,"") | N28: =IF(AND(ISNUMBER(G28),G28>0),G28/IF(ISNUMBER(ダッシュボード!D12),ダッシュボード!D12,1),"") | O28: =IF(ISNUMBER(G28),G28*1+IF(ISNUMBER(H28),H28,0)*5+IF(ISNUMBER(J28),J28,0)*10+IF(ISNUMBER(K28),K28,0)*3,"")
A29: 2026-04-20 | B29: 夕(19:00-20:00) | M29: =IF(AND(ISNUMBER(H29),ISNUMBER(G29),G29>0),H29/G29,"") | N29: =IF(AND(ISNUMBER(G29),G29>0),G29/IF(ISNUMBER(ダッシュボード!D12),ダッシュボード!D12,1),"") | O29: =IF(ISNUMBER(G29),G29*1+IF(ISNUMBER(H29),H29,0)*5+IF(ISNUMBER(J29),J29,0)*10+IF(ISNUMBER(K29),K29,0)*3,"")
A30: 2026-04-20 | B30: 夜1(22:00-22:30) | M30: =IF(AND(ISNUMBER(H30),ISNUMBER(G30),G30>0),H30/G30,"") | N30: =IF(AND(ISNUMBER(G30),G30>0),G30/IF(ISNUMBER(ダッシュボード!D12),ダッシュボード!D12,1),"") | O30: =IF(ISNUMBER(G30),G30*1+IF(ISNUMBER(H30),H30,0)*5+IF(ISNUMBER(J30),J30,0)*10+IF(ISNUMBER(K30),K30,0)*3,"")
A31: 2026-04-20 | B31: 夜2(23:00-23:30) | M31: =IF(AND(ISNUMBER(H31),ISNUMBER(G31),G31>0),H31/G31,"") | N31: =IF(AND(ISNUMBER(G31),G31>0),G31/IF(ISNUMBER(ダッシュボード!D12),ダッシュボード!D12,1),"") | O31: =IF(ISNUMBER(G31),G31*1+IF(ISNUMBER(H31),H31,0)*5+IF(ISNUMBER(J31),J31,0)*10+IF(ISNUMBER(K31),K31,0)*3,"")
A32: 2026-04-21 | B32: 朝(7:30-8:30) | M32: =IF(AND(ISNUMBER(H32),ISNUMBER(G32),G32>0),H32/G32,"") | N32: =IF(AND(ISNUMBER(G32),G32>0),G32/IF(ISNUMBER(ダッシュボード!D12),ダッシュボード!D12,1),"") | O32: =IF(ISNUMBER(G32),G32*1+IF(ISNUMBER(H32),H32,0)*5+IF(ISNUMBER(J32),J32,0)*10+IF(ISNUMBER(K32),K32,0)*3,"")
A33: 2026-04-21 | B33: 昼(12:00-13:00) | M33: =IF(AND(ISNUMBER(H33),ISNUMBER(G33),G33>0),H33/G33,"") | N33: =IF(AND(ISNUMBER(G33),G33>0),G33/IF(ISNUMBER(ダッシュボード!D12),ダッシュボード!D12,1),"") | O33: =IF(ISNUMBER(G33),G33*1+IF(ISNUMBER(H33),H33,0)*5+IF(ISNUMBER(J33),J33,0)*10+IF(ISNUMBER(K33),K33,0)*3,"")
A34: 2026-04-21 | B34: 夕(19:00-20:00) | M34: =IF(AND(ISNUMBER(H34),ISNUMBER(G34),G34>0),H34/G34,"") | N34: =IF(AND(ISNUMBER(G34),G34>0),G34/IF(ISNUMBER(ダッシュボード!D12),ダッシュボード!D12,1),"") | O34: =IF(ISNUMBER(G34),G34*1+IF(ISNUMBER(H34),H34,0)*5+IF(ISNUMBER(J34),J34,0)*10+IF(ISNUMBER(K34),K34,0)*3,"")
A35: 2026-04-21 | B35: 夜1(22:00-22:30) | M35: =IF(AND(ISNUMBER(H35),ISNUMBER(G35),G35>0),H35/G35,"") | N35: =IF(AND(ISNUMBER(G35),G35>0),G35/IF(ISNUMBER(ダッシュボード!D12),ダッシュボード!D12,1),"") | O35: =IF(ISNUMBER(G35),G35*1+IF(ISNUMBER(H35),H35,0)*5+IF(ISNUMBER(J35),J35,0)*10+IF(ISNUMBER(K35),K35,0)*3,"")
A36: 2026-04-21 | B36: 夜2(23:00-23:30) | M36: =IF(AND(ISNUMBER(H36),ISNUMBER(G36),G36>0),H36/G36,"") | N36: =IF(AND(ISNUMBER(G36),G36>0),G36/IF(ISNUMBER(ダッシュボード!D12),ダッシュボード!D12,1),"") | O36: =IF(ISNUMBER(G36),G36*1+IF(ISNUMBER(H36),H36,0)*5+IF(ISNUMBER(J36),J36,0)*10+IF(ISNUMBER(K36),K36,0)*3,"")
A37: 2026-04-22 | B37: 朝(7:30-8:30) | M37: =IF(AND(ISNUMBER(H37),ISNUMBER(G37),G37>0),H37/G37,"") | N37: =IF(AND(ISNUMBER(G37),G37>0),G37/IF(ISNUMBER(ダッシュボード!D12),ダッシュボード!D12,1),"") | O37: =IF(ISNUMBER(G37),G37*1+IF(ISNUMBER(H37),H37,0)*5+IF(ISNUMBER(J37),J37,0)*10+IF(ISNUMBER(K37),K37,0)*3,"")
A38: 2026-04-22 | B38: 昼(12:00-13:00) | M38: =IF(AND(ISNUMBER(H38),ISNUMBER(G38),G38>0),H38/G38,"") | N38: =IF(AND(ISNUMBER(G38),G38>0),G38/IF(ISNUMBER(ダッシュボード!D12),ダッシュボード!D12,1),"") | O38: =IF(ISNUMBER(G38),G38*1+IF(ISNUMBER(H38),H38,0)*5+IF(ISNUMBER(J38),J38,0)*10+IF(ISNUMBER(K38),K38,0)*3,"")
A39: 2026-04-22 | B39: 夕(19:00-20:00) | M39: =IF(AND(ISNUMBER(H39),ISNUMBER(G39),G39>0),H39/G39,"") | N39: =IF(AND(ISNUMBER(G39),G39>0),G39/IF(ISNUMBER(ダッシュボード!D12),ダッシュボード!D12,1),"") | O39: =IF(ISNUMBER(G39),G39*1+IF(ISNUMBER(H39),H39,0)*5+IF(ISNUMBER(J39),J39,0)*10+IF(ISNUMBER(K39),K39,0)*3,"")
A40: 2026-04-22 | B40: 夜1(22:00-22:30) | M40: =IF(AND(ISNUMBER(H40),ISNUMBER(G40),G40>0),H40/G40,"") | N40: =IF(AND(ISNUMBER(G40),G40>0),G40/IF(ISNUMBER(ダッシュボード!D12),ダッシュボード!D12,1),"") | O40: =IF(ISNUMBER(G40),G40*1+IF(ISNUMBER(H40),H40,0)*5+IF(ISNUMBER(J40),J40,0)*10+IF(ISNUMBER(K40),K40,0)*3,"")
...

Sheet ピラー別分析
A1: ■ ピラー別パフォーマンス集計（自動計算）
A3: ピラー | B3: 投稿数 | C3: 平均Imp | D3: 平均ER(%) | E3: 平均スコア | F3: 最高Imp投稿日 | G3: 最低Imp投稿日 | H3: 推奨比率調整
A4: 共感・エンパワメント | B4: =COUNTIF(X投稿ログ!C:C,A4) -> 0 | C4: =IFERROR(AVERAGEIF(X投稿ログ!C:C,A4,X投稿ログ!G:G),0) -> 0 | D4: =IFERROR(AVERAGEIF(X投稿ログ!C:C,A4,X投稿ログ!M:M),0) -> 0 | E4: =IFERROR(AVERAGEIF(X投稿ログ!C:C,A4,X投稿ログ!O:O),0) -> 0 | F4: (データ蓄積後に自動表示) | G4: (データ蓄積後に自動表示)
A5: ブランド・キャスト紹介 | B5: =COUNTIF(X投稿ログ!C:C,A5) -> 0 | C5: =IFERROR(AVERAGEIF(X投稿ログ!C:C,A5,X投稿ログ!G:G),0) -> 0 | D5: =IFERROR(AVERAGEIF(X投稿ログ!C:C,A5,X投稿ログ!M:M),0) -> 0 | E5: =IFERROR(AVERAGEIF(X投稿ログ!C:C,A5,X投稿ログ!O:O),0) -> 0 | F5: (データ蓄積後に自動表示) | G5: (データ蓄積後に自動表示)
A6: お役立ち・コラム | B6: =COUNTIF(X投稿ログ!C:C,A6) -> 0 | C6: =IFERROR(AVERAGEIF(X投稿ログ!C:C,A6,X投稿ログ!G:G),0) -> 0 | D6: =IFERROR(AVERAGEIF(X投稿ログ!C:C,A6,X投稿ログ!M:M),0) -> 0 | E6: =IFERROR(AVERAGEIF(X投稿ログ!C:C,A6,X投稿ログ!O:O),0) -> 0 | F6: (データ蓄積後に自動表示) | G6: (データ蓄積後に自動表示)
A7: キャンペーン・イベント | B7: =COUNTIF(X投稿ログ!C:C,A7) -> 0 | C7: =IFERROR(AVERAGEIF(X投稿ログ!C:C,A7,X投稿ログ!G:G),0) -> 0 | D7: =IFERROR(AVERAGEIF(X投稿ログ!C:C,A7,X投稿ログ!M:M),0) -> 0 | E7: =IFERROR(AVERAGEIF(X投稿ログ!C:C,A7,X投稿ログ!O:O),0) -> 0 | F7: (データ蓄積後に自動表示) | G7: (データ蓄積後に自動表示)
A8: インタラクション | B8: =COUNTIF(X投稿ログ!C:C,A8) -> 0 | C8: =IFERROR(AVERAGEIF(X投稿ログ!C:C,A8,X投稿ログ!G:G),0) -> 0 | D8: =IFERROR(AVERAGEIF(X投稿ログ!C:C,A8,X投稿ログ!M:M),0) -> 0 | E8: =IFERROR(AVERAGEIF(X投稿ログ!C:C,A8,X投稿ログ!O:O),0) -> 0 | F8: (データ蓄積後に自動表示) | G8: (データ蓄積後に自動表示)
A11: ■ 時間帯別パフォーマンス集計
A13: 時間帯 | B13: 投稿数 | C13: 平均Imp | D13: 平均ER(%) | E13: 平均スコア | F13: 評価
A14: 朝(7:30-8:30) | B14: =COUNTIF(X投稿ログ!B:B,A14) -> 90 | C14: =IFERROR(AVERAGEIF(X投稿ログ!B:B,A14,X投稿ログ!G:G),0) -> 0 | D14: =IFERROR(AVERAGEIF(X投稿ログ!B:B,A14,X投稿ログ!M:M),0) -> 0 | E14: =IFERROR(AVERAGEIF(X投稿ログ!B:B,A14,X投稿ログ!O:O),0) -> 0 | F14: =IF(C14=0,"",IF(C14>=AVERAGE($C$14:$C$18),"★ 好調","要改善"))
A15: 昼(12:00-13:00) | B15: =COUNTIF(X投稿ログ!B:B,A15) -> 90 | C15: =IFERROR(AVERAGEIF(X投稿ログ!B:B,A15,X投稿ログ!G:G),0) -> 0 | D15: =IFERROR(AVERAGEIF(X投稿ログ!B:B,A15,X投稿ログ!M:M),0) -> 0 | E15: =IFERROR(AVERAGEIF(X投稿ログ!B:B,A15,X投稿ログ!O:O),0) -> 0 | F15: =IF(C15=0,"",IF(C15>=AVERAGE($C$14:$C$18),"★ 好調","要改善"))
A16: 夕(19:00-20:00) | B16: =COUNTIF(X投稿ログ!B:B,A16) -> 90 | C16: =IFERROR(AVERAGEIF(X投稿ログ!B:B,A16,X投稿ログ!G:G),0) -> 0 | D16: =IFERROR(AVERAGEIF(X投稿ログ!B:B,A16,X投稿ログ!M:M),0) -> 0 | E16: =IFERROR(AVERAGEIF(X投稿ログ!B:B,A16,X投稿ログ!O:O),0) -> 0 | F16: =IF(C16=0,"",IF(C16>=AVERAGE($C$14:$C$18),"★ 好調","要改善"))
A17: 夜1(22:00-22:30) | B17: =COUNTIF(X投稿ログ!B:B,A17) -> 90 | C17: =IFERROR(AVERAGEIF(X投稿ログ!B:B,A17,X投稿ログ!G:G),0) -> 0 | D17: =IFERROR(AVERAGEIF(X投稿ログ!B:B,A17,X投稿ログ!M:M),0) -> 0 | E17: =IFERROR(AVERAGEIF(X投稿ログ!B:B,A17,X投稿ログ!O:O),0) -> 0 | F17: =IF(C17=0,"",IF(C17>=AVERAGE($C$14:$C$18),"★ 好調","要改善"))
A18: 夜2(23:00-23:30) | B18: =COUNTIF(X投稿ログ!B:B,A18) -> 90 | C18: =IFERROR(AVERAGEIF(X投稿ログ!B:B,A18,X投稿ログ!G:G),0) -> 0 | D18: =IFERROR(AVERAGEIF(X投稿ログ!B:B,A18,X投稿ログ!M:M),0) -> 0 | E18: =IFERROR(AVERAGEIF(X投稿ログ!B:B,A18,X投稿ログ!O:O),0) -> 0 | F18: =IF(C18=0,"",IF(C18>=AVERAGE($C$14:$C$18),"★ 好調","要改善"))
A21: ■ 画像有無別パフォーマンス
A23: 条件 | B23: 投稿数 | C23: 平均Imp | D23: 平均ER(%) | E23: 平均スコア
A24: 画像あり | B24: =COUNTIF(X投稿ログ!E:E,"○") -> 0 | C24: =IFERROR(AVERAGEIF(X投稿ログ!E:E,"○",X投稿ログ!G:G),0) -> 0 | D24: =IFERROR(AVERAGEIF(X投稿ログ!E:E,"○",X投稿ログ!M:M),0) -> 0 | E24: =IFERROR(AVERAGEIF(X投稿ログ!E:E,"○",X投稿ログ!O:O),0) -> 0
A25: 画像なし | B25: =COUNTIF(X投稿ログ!E:E,"×") -> 0 | C25: =IFERROR(AVERAGEIF(X投稿ログ!E:E,"×",X投稿ログ!G:G),0) -> 0 | D25: =IFERROR(AVERAGEIF(X投稿ログ!E:E,"×",X投稿ログ!M:M),0) -> 0 | E25: =IFERROR(AVERAGEIF(X投稿ログ!E:E,"×",X投稿ログ!O:O),0) -> 0

Sheet 日次ダイジェスト
A1: 日付 | B1: 曜日 | C1: 投稿数 | D1: 合計Imp | E1: 合計Eng | F1: 合計いいね | G1: 合計RT | H1: 日平均ER(%) | I1: 最高Imp投稿(時間帯) | J1: 最高Impピラー | K1: フォロワー純増 | L1: KW順位変動メモ | M1: 改善アクションメモ
A2: 2026-04-15 | B2: 水 | C2: =COUNTA(X投稿ログ!G2:G6) -> 0 | D2: =SUM(X投稿ログ!G2:G6) -> 0 | E2: =SUM(X投稿ログ!H2:H6) -> 0 | F2: =SUM(X投稿ログ!I2:I6) -> 0 | G2: =SUM(X投稿ログ!J2:J6) -> 0 | H2: =IFERROR(E2/D2,"") | I2: =IFERROR(INDEX(X投稿ログ!B2:B6,MATCH(MAX(X投稿ログ!G2:G6),X投稿ログ!G2:G6,0)),"") | J2: =IFERROR(INDEX(X投稿ログ!C2:C6,MATCH(MAX(X投稿ログ!G2:G6),X投稿ログ!G2:G6,0)),"") | K2: =IFERROR(Xフォロワー推移!C2,"") -> 0
A3: 2026-04-16 | B3: 木 | C3: =COUNTA(X投稿ログ!G7:G11) -> 0 | D3: =SUM(X投稿ログ!G7:G11) -> 0 | E3: =SUM(X投稿ログ!H7:H11) -> 0 | F3: =SUM(X投稿ログ!I7:I11) -> 0 | G3: =SUM(X投稿ログ!J7:J11) -> 0 | H3: =IFERROR(E3/D3,"") | I3: =IFERROR(INDEX(X投稿ログ!B7:B11,MATCH(MAX(X投稿ログ!G7:G11),X投稿ログ!G7:G11,0)),"") | J3: =IFERROR(INDEX(X投稿ログ!C7:C11,MATCH(MAX(X投稿ログ!G7:G11),X投稿ログ!G7:G11,0)),"") | K3: =IFERROR(Xフォロワー推移!C3,"")
A4: 2026-04-17 | B4: 金 | C4: =COUNTA(X投稿ログ!G12:G16) -> 0 | D4: =SUM(X投稿ログ!G12:G16) -> 0 | E4: =SUM(X投稿ログ!H12:H16) -> 0 | F4: =SUM(X投稿ログ!I12:I16) -> 0 | G4: =SUM(X投稿ログ!J12:J16) -> 0 | H4: =IFERROR(E4/D4,"") | I4: =IFERROR(INDEX(X投稿ログ!B12:B16,MATCH(MAX(X投稿ログ!G12:G16),X投稿ログ!G12:G16,0)),"") | J4: =IFERROR(INDEX(X投稿ログ!C12:C16,MATCH(MAX(X投稿ログ!G12:G16),X投稿ログ!G12:G16,0)),"") | K4: =IFERROR(Xフォロワー推移!C4,"")
A5: 2026-04-18 | B5: 土 | C5: =COUNTA(X投稿ログ!G17:G21) -> 0 | D5: =SUM(X投稿ログ!G17:G21) -> 0 | E5: =SUM(X投稿ログ!H17:H21) -> 0 | F5: =SUM(X投稿ログ!I17:I21) -> 0 | G5: =SUM(X投稿ログ!J17:J21) -> 0 | H5: =IFERROR(E5/D5,"") | I5: =IFERROR(INDEX(X投稿ログ!B17:B21,MATCH(MAX(X投稿ログ!G17:G21),X投稿ログ!G17:G21,0)),"") | J5: =IFERROR(INDEX(X投稿ログ!C17:C21,MATCH(MAX(X投稿ログ!G17:G21),X投稿ログ!G17:G21,0)),"") | K5: =IFERROR(Xフォロワー推移!C5,"")
A6: 2026-04-19 | B6: 日 | C6: =COUNTA(X投稿ログ!G22:G26) -> 0 | D6: =SUM(X投稿ログ!G22:G26) -> 0 | E6: =SUM(X投稿ログ!H22:H26) -> 0 | F6: =SUM(X投稿ログ!I22:I26) -> 0 | G6: =SUM(X投稿ログ!J22:J26) -> 0 | H6: =IFERROR(E6/D6,"") | I6: =IFERROR(INDEX(X投稿ログ!B22:B26,MATCH(MAX(X投稿ログ!G22:G26),X投稿ログ!G22:G26,0)),"") | J6: =IFERROR(INDEX(X投稿ログ!C22:C26,MATCH(MAX(X投稿ログ!G22:G26),X投稿ログ!G22:G26,0)),"") | K6: =IFERROR(Xフォロワー推移!C6,"")
A7: 2026-04-20 | B7: 月 | C7: =COUNTA(X投稿ログ!G27:G31) -> 0 | D7: =SUM(X投稿ログ!G27:G31) -> 0 | E7: =SUM(X投稿ログ!H27:H31) -> 0 | F7: =SUM(X投稿ログ!I27:I31) -> 0 | G7: =SUM(X投稿ログ!J27:J31) -> 0 | H7: =IFERROR(E7/D7,"") | I7: =IFERROR(INDEX(X投稿ログ!B27:B31,MATCH(MAX(X投稿ログ!G27:G31),X投稿ログ!G27:G31,0)),"") | J7: =IFERROR(INDEX(X投稿ログ!C27:C31,MATCH(MAX(X投稿ログ!G27:G31),X投稿ログ!G27:G31,0)),"") | K7: =IFERROR(Xフォロワー推移!C7,"")
A8: 2026-04-21 | B8: 火 | C8: =COUNTA(X投稿ログ!G32:G36) -> 0 | D8: =SUM(X投稿ログ!G32:G36) -> 0 | E8: =SUM(X投稿ログ!H32:H36) -> 0 | F8: =SUM(X投稿ログ!I32:I36) -> 0 | G8: =SUM(X投稿ログ!J32:J36) -> 0 | H8: =IFERROR(E8/D8,"") | I8: =IFERROR(INDEX(X投稿ログ!B32:B36,MATCH(MAX(X投稿ログ!G32:G36),X投稿ログ!G32:G36,0)),"") | J8: =IFERROR(INDEX(X投稿ログ!C32:C36,MATCH(MAX(X投稿ログ!G32:G36),X投稿ログ!G32:G36,0)),"") | K8: =IFERROR(Xフォロワー推移!C8,"")
A9: 2026-04-22 | B9: 水 | C9: =COUNTA(X投稿ログ!G37:G41) -> 0 | D9: =SUM(X投稿ログ!G37:G41) -> 0 | E9: =SUM(X投稿ログ!H37:H41) -> 0 | F9: =SUM(X投稿ログ!I37:I41) -> 0 | G9: =SUM(X投稿ログ!J37:J41) -> 0 | H9: =IFERROR(E9/D9,"") | I9: =IFERROR(INDEX(X投稿ログ!B37:B41,MATCH(MAX(X投稿ログ!G37:G41),X投稿ログ!G37:G41,0)),"") | J9: =IFERROR(INDEX(X投稿ログ!C37:C41,MATCH(MAX(X投稿ログ!G37:G41),X投稿ログ!G37:G41,0)),"") | K9: =IFERROR(Xフォロワー推移!C9,"")
A10: 2026-04-23 | B10: 木 | C10: =COUNTA(X投稿ログ!G42:G46) -> 0 | D10: =SUM(X投稿ログ!G42:G46) -> 0 | E10: =SUM(X投稿ログ!H42:H46) -> 0 | F10: =SUM(X投稿ログ!I42:I46) -> 0 | G10: =SUM(X投稿ログ!J42:J46) -> 0 | H10: =IFERROR(E10/D10,"") | I10: =IFERROR(INDEX(X投稿ログ!B42:B46,MATCH(MAX(X投稿ログ!G42:G46),X投稿ログ!G42:G46,0)),"") | J10: =IFERROR(INDEX(X投稿ログ!C42:C46,MATCH(MAX(X投稿ログ!G42:G46),X投稿ログ!G42:G46,0)),"") | K10: =IFERROR(Xフォロワー推移!C10,"")
A11: 2026-04-24 | B11: 金 | C11: =COUNTA(X投稿ログ!G47:G51) -> 0 | D11: =SUM(X投稿ログ!G47:G51) -> 0 | E11: =SUM(X投稿ログ!H47:H51) -> 0 | F11: =SUM(X投稿ログ!I47:I51) -> 0 | G11: =SUM(X投稿ログ!J47:J51) -> 0 | H11: =IFERROR(E11/D11,"") | I11: =IFERROR(INDEX(X投稿ログ!B47:B51,MATCH(MAX(X投稿ログ!G47:G51),X投稿ログ!G47:G51,0)),"") | J11: =IFERROR(INDEX(X投稿ログ!C47:C51,MATCH(MAX(X投稿ログ!G47:G51),X投稿ログ!G47:G51,0)),"") | K11: =IFERROR(Xフォロワー推移!C11,"")
A12: 2026-04-25 | B12: 土 | C12: =COUNTA(X投稿ログ!G52:G56) -> 0 | D12: =SUM(X投稿ログ!G52:G56) -> 0 | E12: =SUM(X投稿ログ!H52:H56) -> 0 | F12: =SUM(X投稿ログ!I52:I56) -> 0 | G12: =SUM(X投稿ログ!J52:J56) -> 0 | H12: =IFERROR(E12/D12,"") | I12: =IFERROR(INDEX(X投稿ログ!B52:B56,MATCH(MAX(X投稿ログ!G52:G56),X投稿ログ!G52:G56,0)),"") | J12: =IFERROR(INDEX(X投稿ログ!C52:C56,MATCH(MAX(X投稿ログ!G52:G56),X投稿ログ!G52:G56,0)),"") | K12: =IFERROR(Xフォロワー推移!C12,"")
A13: 2026-04-26 | B13: 日 | C13: =COUNTA(X投稿ログ!G57:G61) -> 0 | D13: =SUM(X投稿ログ!G57:G61) -> 0 | E13: =SUM(X投稿ログ!H57:H61) -> 0 | F13: =SUM(X投稿ログ!I57:I61) -> 0 | G13: =SUM(X投稿ログ!J57:J61) -> 0 | H13: =IFERROR(E13/D13,"") | I13: =IFERROR(INDEX(X投稿ログ!B57:B61,MATCH(MAX(X投稿ログ!G57:G61),X投稿ログ!G57:G61,0)),"") | J13: =IFERROR(INDEX(X投稿ログ!C57:C61,MATCH(MAX(X投稿ログ!G57:G61),X投稿ログ!G57:G61,0)),"") | K13: =IFERROR(Xフォロワー推移!C13,"")
A14: 2026-04-27 | B14: 月 | C14: =COUNTA(X投稿ログ!G62:G66) -> 0 | D14: =SUM(X投稿ログ!G62:G66) -> 0 | E14: =SUM(X投稿ログ!H62:H66) -> 0 | F14: =SUM(X投稿ログ!I62:I66) -> 0 | G14: =SUM(X投稿ログ!J62:J66) -> 0 | H14: =IFERROR(E14/D14,"") | I14: =IFERROR(INDEX(X投稿ログ!B62:B66,MATCH(MAX(X投稿ログ!G62:G66),X投稿ログ!G62:G66,0)),"") | J14: =IFERROR(INDEX(X投稿ログ!C62:C66,MATCH(MAX(X投稿ログ!G62:G66),X投稿ログ!G62:G66,0)),"") | K14: =IFERROR(Xフォロワー推移!C14,"")
A15: 2026-04-28 | B15: 火 | C15: =COUNTA(X投稿ログ!G67:G71) -> 0 | D15: =SUM(X投稿ログ!G67:G71) -> 0 | E15: =SUM(X投稿ログ!H67:H71) -> 0 | F15: =SUM(X投稿ログ!I67:I71) -> 0 | G15: =SUM(X投稿ログ!J67:J71) -> 0 | H15: =IFERROR(E15/D15,"") | I15: =IFERROR(INDEX(X投稿ログ!B67:B71,MATCH(MAX(X投稿ログ!G67:G71),X投稿ログ!G67:G71,0)),"") | J15: =IFERROR(INDEX(X投稿ログ!C67:C71,MATCH(MAX(X投稿ログ!G67:G71),X投稿ログ!G67:G71,0)),"") | K15: =IFERROR(Xフォロワー推移!C15,"")
A16: 2026-04-29 | B16: 水 | C16: =COUNTA(X投稿ログ!G72:G76) -> 0 | D16: =SUM(X投稿ログ!G72:G76) -> 0 | E16: =SUM(X投稿ログ!H72:H76) -> 0 | F16: =SUM(X投稿ログ!I72:I76) -> 0 | G16: =SUM(X投稿ログ!J72:J76) -> 0 | H16: =IFERROR(E16/D16,"") | I16: =IFERROR(INDEX(X投稿ログ!B72:B76,MATCH(MAX(X投稿ログ!G72:G76),X投稿ログ!G72:G76,0)),"") | J16: =IFERROR(INDEX(X投稿ログ!C72:C76,MATCH(MAX(X投稿ログ!G72:G76),X投稿ログ!G72:G76,0)),"") | K16: =IFERROR(Xフォロワー推移!C16,"")
A17: 2026-04-30 | B17: 木 | C17: =COUNTA(X投稿ログ!G77:G81) -> 0 | D17: =SUM(X投稿ログ!G77:G81) -> 0 | E17: =SUM(X投稿ログ!H77:H81) -> 0 | F17: =SUM(X投稿ログ!I77:I81) -> 0 | G17: =SUM(X投稿ログ!J77:J81) -> 0 | H17: =IFERROR(E17/D17,"") | I17: =IFERROR(INDEX(X投稿ログ!B77:B81,MATCH(MAX(X投稿ログ!G77:G81),X投稿ログ!G77:G81,0)),"") | J17: =IFERROR(INDEX(X投稿ログ!C77:C81,MATCH(MAX(X投稿ログ!G77:G81),X投稿ログ!G77:G81,0)),"") | K17: =IFERROR(Xフォロワー推移!C17,"")
A18: 2026-05-01 | B18: 金 | C18: =COUNTA(X投稿ログ!G82:G86) -> 0 | D18: =SUM(X投稿ログ!G82:G86) -> 0 | E18: =SUM(X投稿ログ!H82:H86) -> 0 | F18: =SUM(X投稿ログ!I82:I86) -> 0 | G18: =SUM(X投稿ログ!J82:J86) -> 0 | H18: =IFERROR(E18/D18,"") | I18: =IFERROR(INDEX(X投稿ログ!B82:B86,MATCH(MAX(X投稿ログ!G82:G86),X投稿ログ!G82:G86,0)),"") | J18: =IFERROR(INDEX(X投稿ログ!C82:C86,MATCH(MAX(X投稿ログ!G82:G86),X投稿ログ!G82:G86,0)),"") | K18: =IFERROR(Xフォロワー推移!C18,"")
A19: 2026-05-02 | B19: 土 | C19: =COUNTA(X投稿ログ!G87:G91) -> 0 | D19: =SUM(X投稿ログ!G87:G91) -> 0 | E19: =SUM(X投稿ログ!H87:H91) -> 0 | F19: =SUM(X投稿ログ!I87:I91) -> 0 | G19: =SUM(X投稿ログ!J87:J91) -> 0 | H19: =IFERROR(E19/D19,"") | I19: =IFERROR(INDEX(X投稿ログ!B87:B91,MATCH(MAX(X投稿ログ!G87:G91),X投稿ログ!G87:G91,0)),"") | J19: =IFERROR(INDEX(X投稿ログ!C87:C91,MATCH(MAX(X投稿ログ!G87:G91),X投稿ログ!G87:G91,0)),"") | K19: =IFERROR(Xフォロワー推移!C19,"")
A20: 2026-05-03 | B20: 日 | C20: =COUNTA(X投稿ログ!G92:G96) -> 0 | D20: =SUM(X投稿ログ!G92:G96) -> 0 | E20: =SUM(X投稿ログ!H92:H96) -> 0 | F20: =SUM(X投稿ログ!I92:I96) -> 0 | G20: =SUM(X投稿ログ!J92:J96) -> 0 | H20: =IFERROR(E20/D20,"") | I20: =IFERROR(INDEX(X投稿ログ!B92:B96,MATCH(MAX(X投稿ログ!G92:G96),X投稿ログ!G92:G96,0)),"") | J20: =IFERROR(INDEX(X投稿ログ!C92:C96,MATCH(MAX(X投稿ログ!G92:G96),X投稿ログ!G92:G96,0)),"") | K20: =IFERROR(Xフォロワー推移!C20,"")
A21: 2026-05-04 | B21: 月 | C21: =COUNTA(X投稿ログ!G97:G101) -> 0 | D21: =SUM(X投稿ログ!G97:G101) -> 0 | E21: =SUM(X投稿ログ!H97:H101) -> 0 | F21: =SUM(X投稿ログ!I97:I101) -> 0 | G21: =SUM(X投稿ログ!J97:J101) -> 0 | H21: =IFERROR(E21/D21,"") | I21: =IFERROR(INDEX(X投稿ログ!B97:B101,MATCH(MAX(X投稿ログ!G97:G101),X投稿ログ!G97:G101,0)),"") | J21: =IFERROR(INDEX(X投稿ログ!C97:C101,MATCH(MAX(X投稿ログ!G97:G101),X投稿ログ!G97:G101,0)),"") | K21: =IFERROR(Xフォロワー推移!C21,"")
A22: 2026-05-05 | B22: 火 | C22: =COUNTA(X投稿ログ!G102:G106) -> 0 | D22: =SUM(X投稿ログ!G102:G106) -> 0 | E22: =SUM(X投稿ログ!H102:H106) -> 0 | F22: =SUM(X投稿ログ!I102:I106) -> 0 | G22: =SUM(X投稿ログ!J102:J106) -> 0 | H22: =IFERROR(E22/D22,"") | I22: =IFERROR(INDEX(X投稿ログ!B102:B106,MATCH(MAX(X投稿ログ!G102:G106),X投稿ログ!G102:G106,0)),"") | J22: =IFERROR(INDEX(X投稿ログ!C102:C106,MATCH(MAX(X投稿ログ!G102:G106),X投稿ログ!G102:G106,0)),"") | K22: =IFERROR(Xフォロワー推移!C22,"")
A23: 2026-05-06 | B23: 水 | C23: =COUNTA(X投稿ログ!G107:G111) -> 0 | D23: =SUM(X投稿ログ!G107:G111) -> 0 | E23: =SUM(X投稿ログ!H107:H111) -> 0 | F23: =SUM(X投稿ログ!I107:I111) -> 0 | G23: =SUM(X投稿ログ!J107:J111) -> 0 | H23: =IFERROR(E23/D23,"") | I23: =IFERROR(INDEX(X投稿ログ!B107:B111,MATCH(MAX(X投稿ログ!G107:G111),X投稿ログ!G107:G111,0)),"") | J23: =IFERROR(INDEX(X投稿ログ!C107:C111,MATCH(MAX(X投稿ログ!G107:G111),X投稿ログ!G107:G111,0)),"") | K23: =IFERROR(Xフォロワー推移!C23,"")
A24: 2026-05-07 | B24: 木 | C24: =COUNTA(X投稿ログ!G112:G116) -> 0 | D24: =SUM(X投稿ログ!G112:G116) -> 0 | E24: =SUM(X投稿ログ!H112:H116) -> 0 | F24: =SUM(X投稿ログ!I112:I116) -> 0 | G24: =SUM(X投稿ログ!J112:J116) -> 0 | H24: =IFERROR(E24/D24,"") | I24: =IFERROR(INDEX(X投稿ログ!B112:B116,MATCH(MAX(X投稿ログ!G112:G116),X投稿ログ!G112:G116,0)),"") | J24: =IFERROR(INDEX(X投稿ログ!C112:C116,MATCH(MAX(X投稿ログ!G112:G116),X投稿ログ!G112:G116,0)),"") | K24: =IFERROR(Xフォロワー推移!C24,"")
A25: 2026-05-08 | B25: 金 | C25: =COUNTA(X投稿ログ!G117:G121) -> 0 | D25: =SUM(X投稿ログ!G117:G121) -> 0 | E25: =SUM(X投稿ログ!H117:H121) -> 0 | F25: =SUM(X投稿ログ!I117:I121) -> 0 | G25: =SUM(X投稿ログ!J117:J121) -> 0 | H25: =IFERROR(E25/D25,"") | I25: =IFERROR(INDEX(X投稿ログ!B117:B121,MATCH(MAX(X投稿ログ!G117:G121),X投稿ログ!G117:G121,0)),"") | J25: =IFERROR(INDEX(X投稿ログ!C117:C121,MATCH(MAX(X投稿ログ!G117:G121),X投稿ログ!G117:G121,0)),"") | K25: =IFERROR(Xフォロワー推移!C25,"")
A26: 2026-05-09 | B26: 土 | C26: =COUNTA(X投稿ログ!G122:G126) -> 0 | D26: =SUM(X投稿ログ!G122:G126) -> 0 | E26: =SUM(X投稿ログ!H122:H126) -> 0 | F26: =SUM(X投稿ログ!I122:I126) -> 0 | G26: =SUM(X投稿ログ!J122:J126) -> 0 | H26: =IFERROR(E26/D26,"") | I26: =IFERROR(INDEX(X投稿ログ!B122:B126,MATCH(MAX(X投稿ログ!G122:G126),X投稿ログ!G122:G126,0)),"") | J26: =IFERROR(INDEX(X投稿ログ!C122:C126,MATCH(MAX(X投稿ログ!G122:G126),X投稿ログ!G122:G126,0)),"") | K26: =IFERROR(Xフォロワー推移!C26,"")
A27: 2026-05-10 | B27: 日 | C27: =COUNTA(X投稿ログ!G127:G131) -> 0 | D27: =SUM(X投稿ログ!G127:G131) -> 0 | E27: =SUM(X投稿ログ!H127:H131) -> 0 | F27: =SUM(X投稿ログ!I127:I131) -> 0 | G27: =SUM(X投稿ログ!J127:J131) -> 0 | H27: =IFERROR(E27/D27,"") | I27: =IFERROR(INDEX(X投稿ログ!B127:B131,MATCH(MAX(X投稿ログ!G127:G131),X投稿ログ!G127:G131,0)),"") | J27: =IFERROR(INDEX(X投稿ログ!C127:C131,MATCH(MAX(X投稿ログ!G127:G131),X投稿ログ!G127:G131,0)),"") | K27: =IFERROR(Xフォロワー推移!C27,"")
A28: 2026-05-11 | B28: 月 | C28: =COUNTA(X投稿ログ!G132:G136) -> 0 | D28: =SUM(X投稿ログ!G132:G136) -> 0 | E28: =SUM(X投稿ログ!H132:H136) -> 0 | F28: =SUM(X投稿ログ!I132:I136) -> 0 | G28: =SUM(X投稿ログ!J132:J136) -> 0 | H28: =IFERROR(E28/D28,"") | I28: =IFERROR(INDEX(X投稿ログ!B132:B136,MATCH(MAX(X投稿ログ!G132:G136),X投稿ログ!G132:G136,0)),"") | J28: =IFERROR(INDEX(X投稿ログ!C132:C136,MATCH(MAX(X投稿ログ!G132:G136),X投稿ログ!G132:G136,0)),"") | K28: =IFERROR(Xフォロワー推移!C28,"")
A29: 2026-05-12 | B29: 火 | C29: =COUNTA(X投稿ログ!G137:G141) -> 0 | D29: =SUM(X投稿ログ!G137:G141) -> 0 | E29: =SUM(X投稿ログ!H137:H141) -> 0 | F29: =SUM(X投稿ログ!I137:I141) -> 0 | G29: =SUM(X投稿ログ!J137:J141) -> 0 | H29: =IFERROR(E29/D29,"") | I29: =IFERROR(INDEX(X投稿ログ!B137:B141,MATCH(MAX(X投稿ログ!G137:G141),X投稿ログ!G137:G141,0)),"") | J29: =IFERROR(INDEX(X投稿ログ!C137:C141,MATCH(MAX(X投稿ログ!G137:G141),X投稿ログ!G137:G141,0)),"") | K29: =IFERROR(Xフォロワー推移!C29,"")
A30: 2026-05-13 | B30: 水 | C30: =COUNTA(X投稿ログ!G142:G146) -> 0 | D30: =SUM(X投稿ログ!G142:G146) -> 0 | E30: =SUM(X投稿ログ!H142:H146) -> 0 | F30: =SUM(X投稿ログ!I142:I146) -> 0 | G30: =SUM(X投稿ログ!J142:J146) -> 0 | H30: =IFERROR(E30/D30,"") | I30: =IFERROR(INDEX(X投稿ログ!B142:B146,MATCH(MAX(X投稿ログ!G142:G146),X投稿ログ!G142:G146,0)),"") | J30: =IFERROR(INDEX(X投稿ログ!C142:C146,MATCH(MAX(X投稿ログ!G142:G146),X投稿ログ!G142:G146,0)),"") | K30: =IFERROR(Xフォロワー推移!C30,"")
A31: 2026-05-14 | B31: 木 | C31: =COUNTA(X投稿ログ!G147:G151) -> 0 | D31: =SUM(X投稿ログ!G147:G151) -> 0 | E31: =SUM(X投稿ログ!H147:H151) -> 0 | F31: =SUM(X投稿ログ!I147:I151) -> 0 | G31: =SUM(X投稿ログ!J147:J151) -> 0 | H31: =IFERROR(E31/D31,"") | I31: =IFERROR(INDEX(X投稿ログ!B147:B151,MATCH(MAX(X投稿ログ!G147:G151),X投稿ログ!G147:G151,0)),"") | J31: =IFERROR(INDEX(X投稿ログ!C147:C151,MATCH(MAX(X投稿ログ!G147:G151),X投稿ログ!G147:G151,0)),"") | K31: =IFERROR(Xフォロワー推移!C31,"")
A32: 2026-05-15 | B32: 金 | C32: =COUNTA(X投稿ログ!G152:G156) -> 0 | D32: =SUM(X投稿ログ!G152:G156) -> 0 | E32: =SUM(X投稿ログ!H152:H156) -> 0 | F32: =SUM(X投稿ログ!I152:I156) -> 0 | G32: =SUM(X投稿ログ!J152:J156) -> 0 | H32: =IFERROR(E32/D32,"") | I32: =IFERROR(INDEX(X投稿ログ!B152:B156,MATCH(MAX(X投稿ログ!G152:G156),X投稿ログ!G152:G156,0)),"") | J32: =IFERROR(INDEX(X投稿ログ!C152:C156,MATCH(MAX(X投稿ログ!G152:G156),X投稿ログ!G152:G156,0)),"") | K32: =IFERROR(Xフォロワー推移!C32,"")
A33: 2026-05-16 | B33: 土 | C33: =COUNTA(X投稿ログ!G157:G161) -> 0 | D33: =SUM(X投稿ログ!G157:G161) -> 0 | E33: =SUM(X投稿ログ!H157:H161) -> 0 | F33: =SUM(X投稿ログ!I157:I161) -> 0 | G33: =SUM(X投稿ログ!J157:J161) -> 0 | H33: =IFERROR(E33/D33,"") | I33: =IFERROR(INDEX(X投稿ログ!B157:B161,MATCH(MAX(X投稿ログ!G157:G161),X投稿ログ!G157:G161,0)),"") | J33: =IFERROR(INDEX(X投稿ログ!C157:C161,MATCH(MAX(X投稿ログ!G157:G161),X投稿ログ!G157:G161,0)),"") | K33: =IFERROR(Xフォロワー推移!C33,"")
A34: 2026-05-17 | B34: 日 | C34: =COUNTA(X投稿ログ!G162:G166) -> 0 | D34: =SUM(X投稿ログ!G162:G166) -> 0 | E34: =SUM(X投稿ログ!H162:H166) -> 0 | F34: =SUM(X投稿ログ!I162:I166) -> 0 | G34: =SUM(X投稿ログ!J162:J166) -> 0 | H34: =IFERROR(E34/D34,"") | I34: =IFERROR(INDEX(X投稿ログ!B162:B166,MATCH(MAX(X投稿ログ!G162:G166),X投稿ログ!G162:G166,0)),"") | J34: =IFERROR(INDEX(X投稿ログ!C162:C166,MATCH(MAX(X投稿ログ!G162:G166),X投稿ログ!G162:G166,0)),"") | K34: =IFERROR(Xフォロワー推移!C34,"")
A35: 2026-05-18 | B35: 月 | C35: =COUNTA(X投稿ログ!G167:G171) -> 0 | D35: =SUM(X投稿ログ!G167:G171) -> 0 | E35: =SUM(X投稿ログ!H167:H171) -> 0 | F35: =SUM(X投稿ログ!I167:I171) -> 0 | G35: =SUM(X投稿ログ!J167:J171) -> 0 | H35: =IFERROR(E35/D35,"") | I35: =IFERROR(INDEX(X投稿ログ!B167:B171,MATCH(MAX(X投稿ログ!G167:G171),X投稿ログ!G167:G171,0)),"") | J35: =IFERROR(INDEX(X投稿ログ!C167:C171,MATCH(MAX(X投稿ログ!G167:G171),X投稿ログ!G167:G171,0)),"") | K35: =IFERROR(Xフォロワー推移!C35,"")
A36: 2026-05-19 | B36: 火 | C36: =COUNTA(X投稿ログ!G172:G176) -> 0 | D36: =SUM(X投稿ログ!G172:G176) -> 0 | E36: =SUM(X投稿ログ!H172:H176) -> 0 | F36: =SUM(X投稿ログ!I172:I176) -> 0 | G36: =SUM(X投稿ログ!J172:J176) -> 0 | H36: =IFERROR(E36/D36,"") | I36: =IFERROR(INDEX(X投稿ログ!B172:B176,MATCH(MAX(X投稿ログ!G172:G176),X投稿ログ!G172:G176,0)),"") | J36: =IFERROR(INDEX(X投稿ログ!C172:C176,MATCH(MAX(X投稿ログ!G172:G176),X投稿ログ!G172:G176,0)),"") | K36: =IFERROR(Xフォロワー推移!C36,"")
A37: 2026-05-20 | B37: 水 | C37: =COUNTA(X投稿ログ!G177:G181) -> 0 | D37: =SUM(X投稿ログ!G177:G181) -> 0 | E37: =SUM(X投稿ログ!H177:H181) -> 0 | F37: =SUM(X投稿ログ!I177:I181) -> 0 | G37: =SUM(X投稿ログ!J177:J181) -> 0 | H37: =IFERROR(E37/D37,"") | I37: =IFERROR(INDEX(X投稿ログ!B177:B181,MATCH(MAX(X投稿ログ!G177:G181),X投稿ログ!G177:G181,0)),"") | J37: =IFERROR(INDEX(X投稿ログ!C177:C181,MATCH(MAX(X投稿ログ!G177:G181),X投稿ログ!G177:G181,0)),"") | K37: =IFERROR(Xフォロワー推移!C37,"")
A38: 2026-05-21 | B38: 木 | C38: =COUNTA(X投稿ログ!G182:G186) -> 0 | D38: =SUM(X投稿ログ!G182:G186) -> 0 | E38: =SUM(X投稿ログ!H182:H186) -> 0 | F38: =SUM(X投稿ログ!I182:I186) -> 0 | G38: =SUM(X投稿ログ!J182:J186) -> 0 | H38: =IFERROR(E38/D38,"") | I38: =IFERROR(INDEX(X投稿ログ!B182:B186,MATCH(MAX(X投稿ログ!G182:G186),X投稿ログ!G182:G186,0)),"") | J38: =IFERROR(INDEX(X投稿ログ!C182:C186,MATCH(MAX(X投稿ログ!G182:G186),X投稿ログ!G182:G186,0)),"") | K38: =IFERROR(Xフォロワー推移!C38,"")
A39: 2026-05-22 | B39: 金 | C39: =COUNTA(X投稿ログ!G187:G191) -> 0 | D39: =SUM(X投稿ログ!G187:G191) -> 0 | E39: =SUM(X投稿ログ!H187:H191) -> 0 | F39: =SUM(X投稿ログ!I187:I191) -> 0 | G39: =SUM(X投稿ログ!J187:J191) -> 0 | H39: =IFERROR(E39/D39,"") | I39: =IFERROR(INDEX(X投稿ログ!B187:B191,MATCH(MAX(X投稿ログ!G187:G191),X投稿ログ!G187:G191,0)),"") | J39: =IFERROR(INDEX(X投稿ログ!C187:C191,MATCH(MAX(X投稿ログ!G187:G191),X投稿ログ!G187:G191,0)),"") | K39: =IFERROR(Xフォロワー推移!C39,"")
A40: 2026-05-23 | B40: 土 | C40: =COUNTA(X投稿ログ!G192:G196) -> 0 | D40: =SUM(X投稿ログ!G192:G196) -> 0 | E40: =SUM(X投稿ログ!H192:H196) -> 0 | F40: =SUM(X投稿ログ!I192:I196) -> 0 | G40: =SUM(X投稿ログ!J192:J196) -> 0 | H40: =IFERROR(E40/D40,"") | I40: =IFERROR(INDEX(X投稿ログ!B192:B196,MATCH(MAX(X投稿ログ!G192:G196),X投稿ログ!G192:G196,0)),"") | J40: =IFERROR(INDEX(X投稿ログ!C192:C196,MATCH(MAX(X投稿ログ!G192:G196),X投稿ログ!G192:G196,0)),"") | K40: =IFERROR(Xフォロワー推移!C40,"")
...

Sheet 週次トレンド
A1: ■ 週次パフォーマンストレンド（自動集計）
A3: 週 | B3: 期間 | C3: 投稿数 | D3: 合計Imp | E3: 合計Eng | F3: 週平均ER(%) | G3: フォロワー純増 | H3: 最高Imp曜日 | I3: 改善点/気づき | J3: 翌週アクション
A4: W1 | B4: 04/15〜04/21 | C4: =SUM(日次ダイジェスト!C2:C8) -> 0 | D4: =SUM(日次ダイジェスト!D2:D8) -> 0 | E4: =SUM(日次ダイジェスト!E2:E8) -> 0 | F4: =IFERROR(E4/D4,"") | G4: =SUM(日次ダイジェスト!K2:K8) -> 0
A5: W2 | B5: 04/22〜04/28 | C5: =SUM(日次ダイジェスト!C9:C15) -> 0 | D5: =SUM(日次ダイジェスト!D9:D15) -> 0 | E5: =SUM(日次ダイジェスト!E9:E15) -> 0 | F5: =IFERROR(E5/D5,"") | G5: =SUM(日次ダイジェスト!K9:K15) -> 0
A6: W3 | B6: 04/29〜05/05 | C6: =SUM(日次ダイジェスト!C16:C22) -> 0 | D6: =SUM(日次ダイジェスト!D16:D22) -> 0 | E6: =SUM(日次ダイジェスト!E16:E22) -> 0 | F6: =IFERROR(E6/D6,"") | G6: =SUM(日次ダイジェスト!K16:K22) -> 0
A7: W4 | B7: 05/06〜05/12 | C7: =SUM(日次ダイジェスト!C23:C29) -> 0 | D7: =SUM(日次ダイジェスト!D23:D29) -> 0 | E7: =SUM(日次ダイジェスト!E23:E29) -> 0 | F7: =IFERROR(E7/D7,"") | G7: =SUM(日次ダイジェスト!K23:K29) -> 0
A8: W5 | B8: 05/13〜05/19 | C8: =SUM(日次ダイジェスト!C30:C36) -> 0 | D8: =SUM(日次ダイジェスト!D30:D36) -> 0 | E8: =SUM(日次ダイジェスト!E30:E36) -> 0 | F8: =IFERROR(E8/D8,"") | G8: =SUM(日次ダイジェスト!K30:K36) -> 0
A9: W6 | B9: 05/20〜05/26 | C9: =SUM(日次ダイジェスト!C37:C43) -> 0 | D9: =SUM(日次ダイジェスト!D37:D43) -> 0 | E9: =SUM(日次ダイジェスト!E37:E43) -> 0 | F9: =IFERROR(E9/D9,"") | G9: =SUM(日次ダイジェスト!K37:K43) -> 0
A10: W7 | B10: 05/27〜06/02 | C10: =SUM(日次ダイジェスト!C44:C50) -> 0 | D10: =SUM(日次ダイジェスト!D44:D50) -> 0 | E10: =SUM(日次ダイジェスト!E44:E50) -> 0 | F10: =IFERROR(E10/D10,"") | G10: =SUM(日次ダイジェスト!K44:K50) -> 0
A11: W8 | B11: 06/03〜06/09 | C11: =SUM(日次ダイジェスト!C51:C57) -> 0 | D11: =SUM(日次ダイジェスト!D51:D57) -> 0 | E11: =SUM(日次ダイジェスト!E51:E57) -> 0 | F11: =IFERROR(E11/D11,"") | G11: =SUM(日次ダイジェスト!K51:K57) -> 0
A12: W9 | B12: 06/10〜06/16 | C12: =SUM(日次ダイジェスト!C58:C64) -> 0 | D12: =SUM(日次ダイジェスト!D58:D64) -> 0 | E12: =SUM(日次ダイジェスト!E58:E64) -> 0 | F12: =IFERROR(E12/D12,"") | G12: =SUM(日次ダイジェスト!K58:K64) -> 0
A13: W10 | B13: 06/17〜06/23 | C13: =SUM(日次ダイジェスト!C65:C71) -> 0 | D13: =SUM(日次ダイジェスト!D65:D71) -> 0 | E13: =SUM(日次ダイジェスト!E65:E71) -> 0 | F13: =IFERROR(E13/D13,"") | G13: =SUM(日次ダイジェスト!K65:K71) -> 0
A14: W11 | B14: 06/24〜06/30 | C14: =SUM(日次ダイジェスト!C72:C78) -> 0 | D14: =SUM(日次ダイジェスト!D72:D78) -> 0 | E14: =SUM(日次ダイジェスト!E72:E78) -> 0 | F14: =IFERROR(E14/D14,"") | G14: =SUM(日次ダイジェスト!K72:K78) -> 0
A15: W12 | B15: 07/01〜07/07 | C15: =SUM(日次ダイジェスト!C79:C85) -> 0 | D15: =SUM(日次ダイジェスト!D79:D85) -> 0 | E15: =SUM(日次ダイジェスト!E79:E85) -> 0 | F15: =IFERROR(E15/D15,"") | G15: =SUM(日次ダイジェスト!K79:K85) -> 0
A16: W13 | B16: 07/08〜07/14 | C16: =SUM(日次ダイジェスト!C86:C91) -> 0 | D16: =SUM(日次ダイジェスト!D86:D91) -> 0 | E16: =SUM(日次ダイジェスト!E86:E91) -> 0 | F16: =IFERROR(E16/D16,"") | G16: =SUM(日次ダイジェスト!K86:K91) -> 0

Sheet AI改善フィードバック
A1: ■ AI投稿生成へのフィードバックループ
A3: このシートの使い方
A4: 毎週月曜に「ピラー別分析」と「日次ダイジェスト」を見て、以下を記録。
A5: 記録内容はCoworkスケジュールタスクのプロンプト改善に直接反映させる。
A7: 記録日 | B7: カテゴリ | C7: 発見事項 | D7: 具体的改善アクション | E7: プロンプト反映済み | F7: 効果確認日
A8: 2026-04-21 | B8: ピラー配分 | C8: 共感系の朝投稿のERが他ピラーの2倍 → 朝は共感固定が最適 | D8: スケジュールタスクの朝投稿指定を『共感固定』に変更
A9: 2026-04-21 | B9: 時間帯 | C9: 22時台のインプレッションが19時台の1.5倍 | D9: 夜1投稿の優先度を上げ、キャスト紹介を22時に移動
A10: 2026-04-21 | B10: 画像効果 | C10: 画像あり投稿のImpが画像なしの3倍 | D10: 全投稿に画像案をつけるようプロンプト強化
A11: 2026-04-28 | B11: 文体 | C11: 質問形式の投稿のリプライ数が通常の5倍 | D11: インタラクション枠以外でも週2回は質問形式を混ぜる指示追加
A12: 2026-04-28 | B12: BAN回避 | C12: 『セラピスト』単語を含む投稿のシャドバン率が高い | D12: 『セラピスト』→『キャスト』に統一するルール追加
A35: ■ プロンプト改善チェックリスト（月次）
A37: □ 最もERが高いピラーの投稿比率を+5%増やしたか
A38: □ 最もERが低いピラーの投稿文体を見直したか
A39: □ 最も反応が良い時間帯にベスト投稿を配置しているか
A40: □ 画像あり/なしのパフォーマンス差を踏まえた指示になっているか
A41: □ 過去1ヶ月で新たに発見したNGワードをBAN回避リストに追加したか
A42: □ フォロワー純増ペースが目標(+38/日)を下回っていたら投稿数を+1本にしたか
A43: □ バズった投稿の共通点(語尾・構成・時事ネタ等)をプロンプトに反映したか

Sheet デイリータスク
A1: 日付 | B1: 曜日 | C1: 時間帯 | D1: カテゴリ | E1: タスク内容 | F1: 担当 | G1: 実施 | H1: 備考
A2: 2026-04-15 | B2: 水 | C2: 09:00-10:00 | D2: 計測 | E2: SearchConsole/GA4で前日順位確認 | F2: SEO責任者
A3: 2026-04-15 | B3: 水 | C3: 09:00-10:00 | D3: 計測 | E3: X公式/サブのインサイト確認・BAN警告チェック | F3: Xオペ
A4: 2026-04-15 | B4: 水 | C4: 10:00-12:00 | D4: X運用 | E4: X朝投稿(共感系)予約・昼投稿(コラム)予約 | F4: Xオペ
A5: 2026-04-15 | B5: 水 | C5: 10:00-12:00 | D5: X運用 | E5: 前日リプ・引用RT対応(目安30分) | F5: Xオペ
A6: 2026-04-15 | B6: 水 | C6: 13:00-17:00 | D6: コンテンツ | E6: ブログ記事執筆(2,000字以上・1日1本) | F6: ライター
A7: 2026-04-15 | B7: 水 | C7: 13:00-17:00 | D7: SEO | E7: 内部リンク調整/構造化データ点検 | F7: SEO責任者
A8: 2026-04-15 | B8: 水 | C8: 17:00-19:00 | D8: X運用 | E8: 夜投稿(キャスト紹介)画像作成・予約 | F8: デザイナー/Xオペ
A9: 2026-04-15 | B9: 水 | C9: 17:00-19:00 | D9: X運用 | E9: キャスト個人垢の投稿チェック・サポート | F9: Xオペ
A10: 2026-04-15 | B10: 水 | C10: 21:00-23:00 | D10: X運用 | E10: 夜投稿リアルタイム監視・リプ返信 | F10: Xオペ
A11: 2026-04-15 | B11: 水 | C11: 21:00-23:00 | D11: X運用 | E11: 翌日投稿ネタの仕込み | F11: Xオペ
A12: 2026-04-16 | B12: 木 | C12: 09:00-10:00 | D12: 計測 | E12: SearchConsole/GA4で前日順位確認 | F12: SEO責任者
A13: 2026-04-16 | B13: 木 | C13: 09:00-10:00 | D13: 計測 | E13: X公式/サブのインサイト確認・BAN警告チェック | F13: Xオペ
... A141: 2026-04-28 | B141: 火 | C141: 21:00-23:00 | D141: X運用 | E141: 翌日投稿ネタの仕込み | F141: Xオペ

Sheet ウィークリー
A1: 曜日 | B1: カテゴリ | C1: タスク | D1: 担当 | E1: 目安時間 | F1: 成果物
A2: 月 | B2: 計測/企画 | C2: 週次KPIレビュー(順位・流入・フォロワー増減)と今週企画決定 | D2: SEO責任者 | E2: 60分 | F2: 週次レポ/企画メモ
A3: 月 | B3: X運用 | C3: 今週のXコンテンツカレンダー確定 | D3: Xオペ | E3: 30分 | F3: 週次カレンダー
A4: 火 | B4: SEO | C4: ロングテール記事1本公開(エリア×ニーズ) | D4: ライター | E4: 半日 | F4: 公開記事URL
A5: 火 | B5: X運用 | C5: 企画投稿1本(アンケート/質問箱) | D5: Xオペ | E5: 30分 | F5: 投稿URL
A6: 水 | B6: コンテンツ | C6: キャストインタビュー/体験談記事1本公開 | D6: ライター | E6: 半日 | F6: 公開記事URL
A7: 木 | B7: X運用 | C7: 深掘り企画(Q&A・裏側スレッド) | D7: Xオペ | E7: 60分 | F7: 投稿URL
A8: 木 | B8: SEO | C8: ブログ2本目の執筆 | D8: ライター | E8: 半日 | F8: 下書き
A9: 金 | B9: 競合分析 | C9: 競合サイト上位・競合Xの動向分析 | D9: SEO責任者 | E9: 60分 | F9: 分析メモ
A10: 金 | B10: コンテンツ | C10: ニュース/業界トレンド記事1本公開 | D10: ライター | E10: 半日 | F10: 公開記事URL
A11: 土 | B11: X運用 | C11: 週末キャンペーン/キャスト紹介集中投稿 | D11: Xオペ | E11: 60分 | F11: 投稿URL
A12: 日 | B12: 運用点検 | C12: 翌週コンテンツカレンダー確定・バックアップ・サブ垢点検 | D12: Xオペ | E12: 45分 | F12: 翌週カレンダー

Sheet マンスリー
A1: タイミング | B1: カテゴリ | C1: タスク | D1: 担当 | E1: 成果物 | F1: 頻度
A2: 月初(1-3日) | B2: 計測 | C2: SC/GA4/Xアナリ 月次レポート作成・KGI/KPI進捗レビュー | D2: SEO責任者 | E2: 月次レポ | F2: 毎月
A3: 月初(1-3日) | B3: 企画 | C3: 月次コンテンツテーマ策定(SEO/X) | D3: SEO責任者 | E3: 企画書 | F3: 毎月
A4: 中旬(10-15日) | B4: SEO | C4: 競合SEO上位10サイト分析・KW GAP抽出 | D4: SEO責任者 | E4: GAP分析シート | F4: 毎月
A5: 中旬(10-15日) | B5: PR/被リンク | C5: 業界誌・ライフスタイルメディアへ寄稿営業2件以上 | D5: 責任者 | E5: 営業ログ | F5: 毎月
A6: 月末(25-末) | B6: SEO | C6: 順位11-30位記事のリライト対象選定と実施 | D6: ライター | E6: リライト記事 | F6: 毎月
A7: 月末(25-末) | B7: X運用 | C7: X BANリスク点検(警告・センシティブ判定確認) | D7: Xオペ | E7: 点検レポ | F7: 毎月
A8: 月末(25-末) | B8: ブランド | C8: キャンペーン企画の振り返りと次月企画立案 | D8: 責任者 | E8: 企画書 | F8: 毎月
A9: 四半期 | B9: 戦略 | C9: KGI四半期レビュー・戦略修正 | D9: 責任者 | E9: 戦略改訂版 | F9: Q毎

Sheet KW順位トラッキング
A1: KW | B1: エリア | C1: 優先度 | D1: 月間検索Vol(想定) | E1: 現順位 | F1: 1ヶ月前 | G1: 2ヶ月前 | H1: 3ヶ月前 | I1: 目標順位 | J1: 達成期限 | K1: 担当記事URL
A2: ストロベリーボーイズ | B2: 指名 | C2: S | D2: 維持 | I2: 1 | J2: 通年
A3: ストロベリーボーイズ 横浜 | B3: 指名 | C3: S | D3: 維持 | I3: 1 | J3: 通年
A4: ストロベリーボーイズ 福岡 | B4: 指名 | C4: S | D4: 維持 | I4: 1 | J4: 通年
A5: 女性用風俗 横浜 | B5: 横浜 | C5: S | D5: 1,000-3,000 | I5: 1 | J5: 2026-12-31
A6: 女性用風俗 神奈川 | B6: 神奈川 | C6: S | D6: 500-1,500 | I6: 1 | J6: 2026-12-31
A7: 女性用風俗 福岡 | B7: 福岡 | C7: S | D7: 1,000-2,500 | I7: 1 | J7: 2026-12-31
A8: 女性用風俗 博多 | B8: 博多 | C8: S | D8: 500-1,500 | I8: 1 | J8: 2026-12-31
A9: 女風 横浜 | B9: 横浜 | C9: A | D9: 500-1,200 | I9: 3 | J9: 2026-12-31
A10: 女風 福岡 | B10: 福岡 | C10: A | D10: 500-1,200 | I10: 3 | J10: 2026-12-31
A11: 女性用風俗 おすすめ 横浜 | B11: 横浜 | C11: A | D11: 200-500 | I11: 3 | J11: 2026-09-30
A12: 女性用風俗 おすすめ 福岡 | B12: 福岡 | C12: A | D12: 200-500 | I12: 3 | J12: 2026-09-30
A13: 女性用風俗 口コミ 横浜 | B13: 横浜 | C13: A | D13: 100-300 | I13: 5 | J13: 2026-09-30
... A18: 女性用風俗 | B18: ビッグ | C18: A | D18: 40,000+ | I18: 10 | J18: 2026-12-31

Sheet Xフォロワー推移
A1: 日付 | B1: 公式フォロワー | C1: 純増 | D1: 公式Imp | E1: 公式ER(%) | F1: サブフォロワー | G1: サブ純増 | H1: メモ
A2: 2026-04-15
A3: 2026-04-16 | C3: =IF(AND(ISNUMBER(B3),ISNUMBER(B2)),B3-B2,"") | G3: =IF(AND(ISNUMBER(F3),ISNUMBER(F2)),F3-F2,"")
A4: 2026-04-17 | C4: =IF(AND(ISNUMBER(B4),ISNUMBER(B3)),B4-B3,"") | G4: =IF(AND(ISNUMBER(F4),ISNUMBER(F3)),F4-F3,"")
A5: 2026-04-18 | C5: =IF(AND(ISNUMBER(B5),ISNUMBER(B4)),B5-B4,"") | G5: =IF(AND(ISNUMBER(F5),ISNUMBER(F4)),F5-F4,"")
A6: 2026-04-19 | C6: =IF(AND(ISNUMBER(B6),ISNUMBER(B5)),B6-B5,"") | G6: =IF(AND(ISNUMBER(F6),ISNUMBER(F5)),F6-F5,"")
A7: 2026-04-20 | C7: =IF(AND(ISNUMBER(B7),ISNUMBER(B6)),B7-B6,"") | G7: =IF(AND(ISNUMBER(F7),ISNUMBER(F6)),F7-F6,"")
A8: 2026-04-21 | C8: =IF(AND(ISNUMBER(B8),ISNUMBER(B7)),B8-B7,"") | G8: =IF(AND(ISNUMBER(F8),ISNUMBER(F7)),F8-F7,"")
A9: 2026-04-22 | C9: =IF(AND(ISNUMBER(B9),ISNUMBER(B8)),B9-B8,"") | G9: =IF(AND(ISNUMBER(F9),ISNUMBER(F8)),F9-F8,"")
A10: 2026-04-23 | C10: =IF(AND(ISNUMBER(B10),ISNUMBER(B9)),B10-B9,"") | G10: =IF(AND(ISNUMBER(F10),ISNUMBER(F9)),F10-F9,"")
A11: 2026-04-24 | C11: =IF(AND(ISNUMBER(B11),ISNUMBER(B10)),B11-B10,"") | G11: =IF(AND(ISNUMBER(F11),ISNUMBER(F10)),F11-F10,"")
A12: 2026-04-25 | C12: =IF(AND(ISNUMBER(B12),ISNUMBER(B11)),B12-B11,"") | G12: =IF(AND(ISNUMBER(F12),ISNUMBER(F11)),F12-F11,"")
A13: 2026-04-26 | C13: =IF(AND(ISNUMBER(B13),ISNUMBER(B12)),B13-B12,"") | G13: =IF(AND(ISNUMBER(F13),ISNUMBER(F12)),F13-F12,"")
A14: 2026-04-27 | C14: =IF(AND(ISNUMBER(B14),ISNUMBER(B13)),B14-B13,"") | G14: =IF(AND(ISNUMBER(F14),ISNUMBER(F13)),F14-F13,"")
... A61: 2026-06-13 | C61: =IF(AND(ISNUMBER(B61),ISNUMBER(B60)),B61-B60,"") | G61: =IF(AND(ISNUMBER(F61),ISNUMBER(F60)),F61-F60,"")

Sheet Xコンテンツピラー
A1: ピラー | B1: 目標比率 | C1: トーン | D1: 投稿例 | E1: NG表現 | F1: 目安頻度
A2: 共感・エンパワメント | B2: 30% | C2: 上品・優しい | D2: 女性が自分を大切にする言葉、日常の気づき、名言 | E2: 性的直接語/露出画像 | F2: 週8-10本
A3: ブランド・キャスト紹介 | B3: 25% | C3: 温かみ・親しみ | D3: 新人紹介、セラピスト日常、裏側ショート動画 | E3: 過度な煽り/露出 | F3: 週7-8本
A4: お役立ち・コラム | B4: 20% | C4: 落ち着き・信頼 | D4: 選び方Q&A、初めての方向けガイド、記事誘導 | E4: 医療断定表現 | F4: 週5-6本
A5: キャンペーン・イベント | B5: 15% | C5: 特別感 | D5: 割引告知、プレゼント、相互企画 | E5: 金額直接/URL連投 | F5: 週4-5本
A6: インタラクション | B6: 10% | C6: 親しみ・双方向 | D6: 質問箱、アンケート、リプ引用 | E6: 煽り・挑発 | F6: 週3本

Sheet BANリスク管理
A1: ■ X BANリスク管理・禁止ワードリスト
A3: 種別 | B3: NGワード/表現 | C3: 代替表現 | D3: リスクレベル
A4: 直接語 | B4: セックス/性行為/挿入/射精 | C4: 癒やしの時間/特別な体験 | D4: 高
A5: 直接語 | B5: アダルト/エロ | C5: 女性の癒やし/大人の時間 | D5: 高
A6: 断定 | B6: 絶対安全/必ず満足/100% | C6: 多くのお客様にご好評/丁寧に | D6: 中
A7: 医療 | B7: 治る/効く/改善する/治療 | C7: (使用しない) | D7: 高
A8: 金銭 | B8: 本文に料金総額直記 | C8: サイトでご案内/プロフィール参照 | D8: 中
A9: URL | B9: 短縮URL連投・本文複数URL | C9: 投稿末尾に1本のみ | D9: 高
A10: 画像 | B10: 肌面積30%超/下着直視 | C10: シルエット/上品な構図 | D10: 高
A11: 連絡先 | B11: TEL/LINE ID直記載 | C11: サイトの予約フォーム誘導 | D11: 中
A12: 行動 | B12: 1日フォロー20超/DM連投 | C12: オーガニック中心・1日20以内 | D12: 中
A15: ■ 緊急時対応プレイブック
A16: ケース | B16: 即時アクション(24h以内) | C16: 担当 | D16: 完了チェック
A17: X公式垢BAN | B17: サブ垢から告知→サイトLPリンク差替→異議申立(英文)→解除不可ならサブ垢昇格 | C17: Xオペ/責任者
A18: X公式垢シャドバン | B18: 直近3日の投稿見直し・禁止ワード点検・1日投稿数を1-2本に抑制 | C18: Xオペ
A19: SEO順位急落 | B19: Search Console手動対策確認→直近2週間の変更確認→コアアップデート有無確認→72h以内改善 | C19: SEO責任者
A20: キャスト不祥事報道 | B20: 広報対応プロトコル起動・該当キャスト投稿停止・公式コメント準備 | C20: 責任者
A21: サイトダウン | B21: ホスティング状況確認・バックアップから復旧・ステータス告知 | C21: 技術担当

Sheet 記事管理
A1: 公開予定日 | B1: タイプ | C1: エリア | D1: ターゲットKW | E1: タイトル案 | F1: 担当 | G1: ステータス | H1: 公開URL | I1: 文字数 | J1: 備考
A2: 2026-04-20 | B2: エリアLP | C2: 横浜 | D2: 女性用風俗 横浜 | E2: 【2026最新】横浜エリアで選ばれる女性用風俗完全ガイド | F2: ライター | G2: 執筆中 | I2: 5000 | J2: 主力コンテンツ
A3: 2026-04-22 | B3: エリアLP | C3: 福岡 | D3: 女性用風俗 福岡 | E3: 福岡・博多で体験できる女性用風俗の魅力と選び方 | F3: ライター | G3: 企画 | I3: 5000 | J3: 主力コンテンツ
A4: 2026-04-25 | B4: ガイド | C4: 全国 | D4: 女性用風俗 初めて | E4: 初めての女性用風俗｜失敗しない選び方と心構え | F4: ライター | G4: 企画 | I4: 3500
A5: 2026-04-28 | B5: Q&A | C5: 全国 | D5: 女性用風俗 口コミ | E5: 女性用風俗Q&A 50選｜みんなが気になる疑問に回答 | F5: ライター | G5: 企画 | I5: 6000 | J5: FAQスキーマ
A6: 2026-05-02 | B6: キャスト | C6: 横浜 | D6: ストロベリーボーイズ 横浜 | E6: 【キャスト紹介】横浜在籍セラピスト◯◯さんの想い | F6: ライター | G6: 企画 | I6: 2500 | J6: 指名拡張

Sheet 競合バズ投稿
A1: ■ 競合バズ投稿ライブラリ（Grokで収集 → 投稿改善に活用）
A2: 使い方: 週2回、Grokに『女性用風俗 OR 女風 OR レズ風俗 で直近7日にバズったX投稿を10件教えて』と聞き、結果をここに貼る
A4: 収集日 | B4: 競合アカウント | C4: 投稿テキスト(要約) | D4: Imp(概算) | E4: いいね | F4: RT | G4: バズ要因分析 | H4: 自店に活かせるポイント | I4: 活用済み
A5: 2026-04-17 | B5: @xxx_lady | C5: 初めての女風、正直ドキドキしたけど…(体験談形式) | D5: 50,000 | E5: 320 | F5: 85 | G5: 体験談の生々しさ+共感導入 | H5: 体験談形式の投稿を月2回導入
A6: 2026-04-17 | B6: @yyy_relax | C6: 「癒されたい」って言葉、本当は…(名言リライト系) | D6: 35,000 | E6: 210 | F6: 40 | G6: 共感×名言の組み合わせ+深夜投稿 | H6: 23時台に共感名言系を配置
A7: 2026-04-17 | B7: @zzz_care | C7: アンケート: 女風に興味ある方、きっかけは？ | D7: 28,000 | E7: 150 | F7: 20 | G7: 質問形式でリプ誘導→アルゴ優遇 | H7: 週1のアンケート投稿を必須化
A40: ■ Grokへのプロンプトテンプレート（コピペ用）
A42: 【バズ投稿収集】
A43: X上で「女性用風俗」「女風」「レディースエステ」に関連する投稿のうち、直近7日間でインプレッション・エンゲージメントが最も高かったものを10件教えてください。各投稿について: アカウント名、投稿テキスト要約、推定インプレッション数、いいね数、RT数、バズった理由の分析をお願いします。
A45: 【アルゴリズム分析】
A46: Xの最新アルゴリズムについて教えてください。2026年4月現在、どのような投稿がアルゴリズムに優遇されていますか？特に: リプライの重み、画像vs動画の優遇度、投稿時間帯の影響、ハッシュタグの効果について最新情報をお願いします。
A48: 【ターゲット層分析】
A49: X上で「癒し」「セルフケア」「自分へのご褒美」「疲れた」などのキーワードで投稿している20-40代女性ユーザーの最近のトレンドを教えてください。どんな話題・悩み・興味が多いですか？投稿の傾向を10個にまとめてください。

Sheet トレンド・時事
A1: ■ 業界トレンド・時事ネタDB（Perplexityで収集 → 投稿・記事ネタに活用）
A2: 使い方: 週1回、Perplexityで業界ニュース/ターゲット層トレンドを検索し、投稿ネタ候補としてストック
A4: 収集日 | B4: ソース | C4: カテゴリ | D4: トレンド/ニュース概要 | E4: 投稿ネタ転用案 | F4: 記事ネタ転用案 | G4: 使用済み | H4: 出典URL
A5: 2026-04-17 | B5: Perplexity | C5: 業界動向 | D5: 女性向けリラクゼーション市場が前年比120%成長(矢野経済研究所) | E5: 「女性が癒しを求める時代、プロの手で…」系投稿 | F5: 【データ記事】女性用リラクゼーション市場の伸びとその背景
A6: 2026-04-17 | B6: Perplexity | C6: ターゲット層 | D6: 30代女性の6割が『自分時間の確保』を最重要課題と回答(マイナビ調査) | E6: 「自分だけの時間、最後にいつ過ごしましたか？」共感投稿 | F6: 働く女性の自分時間調査レポート→サービス紹介
A7: 2026-04-17 | B7: Grok/X | C7: Xトレンド | D7: 「#セルフケア」がX上で急上昇。投稿数が前月比3倍 | E7: ハッシュタグ #セルフケア を投稿に積極採用 | F7: セルフケア特集記事(女風をセルフケアの一環として訴求)
A40: ■ Perplexityへのプロンプトテンプレート（コピペ用）
A42: 【業界トレンド】
A43: 日本の女性向けリラクゼーション・セラピー業界の2026年最新トレンドを教えてください。市場規模、成長率、注目サービス、消費者の変化について、出典付きでまとめてください。
A45: 【ターゲット層リサーチ】
A46: 日本の25-40歳女性の「癒し」「リラクゼーション」「セルフケア」に関する最新の消費動向・意識調査を教えてください。特に: 利用頻度、予算感、求めているもの、SNSでの情報収集行動について。出典付きでお願いします。
A48: 【横浜ローカル】
A49: 横浜・みなとみらいエリアの女性向けリラクゼーション・スパ・セラピーの最新情報を教えてください。新規オープン店舗、人気スポット、地域の特徴的なトレンドについて。
A51: 【福岡ローカル】
A52: 福岡・博多・天神エリアの女性向けリラクゼーション・セラピーの最新情報を教えてください。地域特有のトレンドや、東京・大阪との違いについても。

Sheet Xアルゴ動向
A1: ■ Xアルゴリズム変動ログ（Grokで収集 → 運用ルール即時更新）
A2: Grokに『Xの最新アルゴリズム変更』を月2回聞き、運用ルールを即反映する
A4: 確認日 | B4: 情報源 | C4: アルゴリズム変更内容 | D4: 影響度 | E4: 運用への影響 | F4: 対応アクション | G4: 反映済み
A5: 2026-04-17 | B5: Grok | C5: リプライチェーンの重みが増加。会話を生む投稿がFor Youに優遇 | D5: 高 | E5: 質問形式・意見を促す投稿の優先度UP | F5: インタラクション枠を10%→15%に引上げ検討
A6: 2026-04-17 | B6: Grok | C6: 画像4枚カルーセルのImpが単画像の2倍に | D6: 中 | E6: キャスト紹介は4枚カルーセル推奨 | F6: 画像案を『4枚セット』前提に変更
A7: 2026-04-17 | B7: X公式 | C7: センシティブ判定AIが強化。肌色面積の閾値が下がった模様 | D7: 高 | E7: キャスト写真はさらに控えめに | F7: BAN回避ルールの肌面積基準を20%に引下げ
A30: ■ 現在の運用ルール（アルゴ対応版）— 最終更新日をここに記録
A32: 項目 | B32: 現在のルール
A33: 投稿形式 | B33: テキスト+画像4枚カルーセルが最強。動画は30秒以内ショート推奨
A34: リプライ誘導 | B34: 全投稿の30%以上に質問/意見募集を含める
A35: 投稿間隔 | B35: 最低30分。1日5投稿が上限(過投稿ペナルティ回避)
A36: ハッシュタグ | B36: 1投稿あたり1-2個。3個以上はスパム判定リスク
A37: URL | B37: 投稿末尾に1本のみ。本文中URLはImp低下要因
A38: 引用RT | B38: 通常RTより引用RTの方がアルゴ優遇。積極的に引用する
A39: 投稿時間 | B39: 22-23時がピーク。7-8時の朝投稿も安定
A40: センシティブ | B40: 肌面積20%以下。シルエット・イラスト・風景を推奨
